Workbook

Sheet MLB Teams Payroll
A1: Team | B1: Record | C1: Tax Payroll | D1: Cap Space | E1: Luxury Tax Bill | F1: Year
A2: LAD | B2: 93-69 | C2: 416823208 | D2: -175823208 | E2: 168805529 | F2: 2025
A3: NYM | B3: 83-79 | C3: 341471934 | D3: -100471934 | E3: 85919127 | F3: 2025
A4: NYY | B4: 94-68 | C4: 318095908 | D4: -77095908 | E4: 60205499 | F4: 2025
A5: PHI | B5: 96-66 | C5: 308027103 | D5: -67027103 | E5: 49129813 | F5: 2025
A6: TOR | B6: 94-68 | C6: 280036096 | D6: -39036096 | E6: 10000000 | F6: 2025
A7: SD | B7: 90-72 | C7: 273108464 | D7: -32108464 | E7: 10000000 | F7: 2025
A8: BOS | B8: 89-73 | C8: 245685904 | D8: -4685904 | E8: 937181 | F8: 2025
A9: HOU | B9: 87-75 | C9: 244685373 | D9: -3685373 | E9: 1105612 | F9: 2025
A10: TEX | B10: 81-81 | C10: 239418828 | D10: 1581172 | E10: - | F10: 2025
A11: ATL | B11: 76-86 | C11: 237534306 | D11: 3465694 | E11: - | F11: 2025
A12: CHC | B12: 92-70 | C12: 227017252 | D12: 13982748 | E12: - | F12: 2025
A13: LAA | B13: 72-90 | C13: 220094210 | D13: 20905790 | E13: - | F13: 2025
A14: SF | B14: 81-81 | C14: 217982568 | D14: 23017432 | E14: - | F14: 2025
A15: ARI | B15: 80-82 | C15: 211450764 | D15: 29549236 | E15: - | F15: 2025
A16: SEA | B16: 90-72 | C16: 190939946 | D16: 50060054 | E16: - | F16: 2025
A17: BAL | B17: 75-87 | C17: 175904710 | D17: 65095290 | E17: - | F17: 2025
A18: KC | B18: 82-80 | C18: 174333472 | D18: 66666528 | E18: - | F18: 2025
A19: DET | B19: 87-75 | C19: 168688606 | D19: 72311394 | E19: - | F19: 2025
A20: STL | B20: 78-84 | C20: 156648581 | D20: 84351419 | E20: - | F20: 2025
A21: MIL | B21: 97-65 | C21: 145656240 | D21: 95343760 | E21: - | F21: 2025
... A31: MIA | B31: 79-83 | C31: 85266547 | D31: 155733453 | E31: - | F31: 2025
A32: LAD | B32: 98-64 | C32: 353015360 | D32: =237000000 - 'MLB Teams Payroll'!$C32 -> -116015360 | E32: 103016896 | F32: 2024
A33: NYM | B33: 89-73 | C33: 347650554 | D33: =237000000 - 'MLB Teams Payroll'!$C33 -> -110650554 | E33: 97115609 | F33: 2024
A34: NYY | B34: 94-68 | C34: 316192828 | D34: =237000000 - 'MLB Teams Payroll'!$C34 -> -79192828 | E34: 62512111 | F34: 2024
A35: ATL | B35: 89-73 | C35: 276144038 | D35: =237000000 - 'MLB Teams Payroll'!$C35 -> -39144038 | E35: 14026496 | F35: 2024
A36: TEX | B36: 78-84 | C36: 268445491 | D36: =237000000 - 'MLB Teams Payroll'!$C36 -> -31445491 | E36: 10807106 | F36: 2024
A37: HOU | B37: 88-73 | C37: 264759503 | D37: =237000000 - 'MLB Teams Payroll'!$C37 -> -27759503 | E37: 6483041 | F37: 2024
A38: PHI | B38: 95-67 | C38: 264314134 | D38: =237000000 - 'MLB Teams Payroll'!$C38 -> -27314134 | E38: 14351954 | F38: 2024
A39: SF | B39: 80-82 | C39: 249108939 | D39: =237000000 - 'MLB Teams Payroll'!$C39 -> -12108939 | E39: 2421788 | F39: 2024
A40: CHC | B40: 83-79 | C40: 239851546 | D40: =237000000 - 'MLB Teams Payroll'!$C40 -> -2851546 | E40: 570309 | F40: 2024
A41: TOR | B41: 74-88 | C41: 233920561 | D41: =237000000 - 'MLB Teams Payroll'!$C41 -> 3079439 | E41: - | F41: 2024
A42: SD | B42: 93-69 | C42: 227767386 | D42: =237000000 - 'MLB Teams Payroll'!$C42 -> 9232614 | E42: - | F42: 2024
A43: BOS | B43: 81-81 | C43: 226128399 | D43: =237000000 - 'MLB Teams Payroll'!$C43 -> 10871601 | E43: - | F43: 2024
A44: ARI | B44: 89-73 | C44: 223742984 | D44: =237000000 - 'MLB Teams Payroll'!$C44 -> 13257016 | E44: - | F44: 2024
A45: STL | B45: 83-79 | C45: 207746783 | D45: =237000000 - 'MLB Teams Payroll'!$C45 -> 29253217 | E45: - | F45: 2024
A46: LAA | B46: 63-99 | C46: 189997640 | D46: =237000000 - 'MLB Teams Payroll'!$C46 -> 47002360 | E46: - | F46: 2024
A47: COL | B47: 61-101 | C47: 171035859 | D47: =237000000 - 'MLB Teams Payroll'!$C47 -> 65964141 | E47: - | F47: 2024
A48: SEA | B48: 85-77 | C48: 167805639 | D48: =237000000 - 'MLB Teams Payroll'!$C48 -> 69194361 | E48: - | F48: 2024
A49: MIL | B49: 93-69 | C49: 162786812 | D49: =237000000 - 'MLB Teams Payroll'!$C49 -> 74213188 | E49: - | F49: 2024
...

Sheet Luxury Tax Threshold
A1: Luxury Tax Threshold | B1: Year
A2: 241000000 | B2: 2025
A3: 237000000 | B3: 2024
A4: 233000000 | B4: 2023
A5: 230000000 | B5: 2022
A6: 210000000 | B6: 2021
A7: 208000000 | B7: 2020
A8: 206000000 | B8: 2019
A9: 197000000 | B9: 2018
A10: 195000000 | B10: 2017
A11: 189000000 | B11: 2016
A12: 189000000 | B12: 2015
A13: 189000000 | B13: 2014
... A15: 178000000 | B15: 2012

Sheet World Series
A1: WS Champion | B1: WS Runner Up | C1: Year
A2: LAD | B2: TOR | C2: 2025
A3: LAD | B3: NYY | C3: 2024
A4: TEX | B4: ARI | C4: 2023
A5: HOU | B5: PHI | C5: 2022
A6: ATL | B6: HOU | C6: 2021
A7: LAD | B7: TB | C7: 2020
A8: WSH | B8: HOU | C8: 2019
A9: BOS | B9: LAD | C9: 2018
A10: HOU | B10: LAD | C10: 2017
A11: CHC | B11: CLE | C11: 2016
A12: KC | B12: NYM | C12: 2015
A13: SFG | B13: KCR | C13: 2014
... A15: SF | B15: DET | C15: 2012
